<?xml version="1.0" encoding="utf-8"?>
<!-- =================================================================================== -->
<!-- |    This document was autogenerated by xacro from mrobot.urdf.xacro              | -->
<!-- |    EDITING THIS FILE BY HAND IS NOT RECOMMENDED                                 | -->
<!-- =================================================================================== -->
<robot name="mrobot">
  <material name="Green">
    <color rgba="0.0 0.8 0.0 1.0"/>
  </material>
  <material name="yellow">
    <color rgba="1 0.4 0 1"/>
  </material>
  <material name="black">
    <color rgba="0 0 0 0.95"/>
  </material>
  <material name="gray">
    <color rgba="0.75 0.75 0.75 1"/>
  </material>
  <link name="base_footprint">
    <visual>
      <origin rpy="0 0 0" xyz="0 0 0"/>
      <geometry>
        <box size="0.001 0.001 0.001"/>
      </geometry>
    </visual>
  </link>
  <link name="base_link">
    <inertial>
      <mass value="2"/>
      <origin xyz="0 0 0.0"/>
      <inertia ixx="0.01" ixy="0.0" ixz="0.0" iyy="0.01" iyz="0.0" izz="0.5"/>
    </inertial>
    <visual>
      <origin rpy="0 0 0" xyz=" 0 0 0"/>
      <geometry>
        <cylinder length="0.005" radius="0.13"/>
      </geometry>
      <material name="yellow"/>
    </visual>
    <collision>
      <origin rpy="0 0 0" xyz="0 0 0"/>
      <geometry>
        <cylinder length="0.005" radius="0.13"/>
      </geometry>
    </collision>
  </link>
  <joint name="base_footprint_joint" type="fixed">
    <origin rpy="0 0 0" xyz="0 0 0.033"/>
    <parent link="base_footprint"/>
    <child link="base_link"/>
  </joint>
  <link name="left_motor">
    <inertial>
      <origin xyz="0.0 0 0"/>
      <mass value="0.1"/>
      <inertia ixx="0.001" ixy="0.0" ixz="0.0" iyy="0.001" iyz="0.0" izz="0.001"/>
    </inertial>
    <visual>
      <origin rpy="1.570795 0 0" xyz="0 0 0"/>
      <geometry>
        <cylinder length="0.08" radius="0.02"/>
      </geometry>
      <material name="gray"/>
    </visual>
    <collision>
      <origin rpy="1.570795 0 0" xyz="0 0 0"/>
      <geometry>
        <cylinder length="0.08" radius="0.02"/>
      </geometry>
    </collision>
  </link>
  <joint name="base_left_motor_joint" type="fixed">
    <origin rpy="0 0 0" xyz="-0.055 0.075 0"/>
    <parent link="base_link"/>
    <child link="left_motor"/>
  </joint>
  <link name="left_wheel_link">
    <inertial>
      <origin xyz="0 0 0"/>
      <mass value="0.01"/>
      <inertia ixx="0.001" ixy="0.0" ixz="0.0" iyy="0.001" iyz="0.0" izz="0.001"/>
    </inertial>
    <visual>
      <origin rpy="1.570795 0 0" xyz="0 0 0"/>
      <geometry>
        <cylinder length="0.017" radius="0.033"/>
      </geometry>
      <material name="white">
        <color rgba="1 1 1 0.9"/>
      </material>
    </visual>
    <collision>
      <origin rpy="1.570795 0 0" xyz="0 0 0"/>
      <geometry>
        <cylinder length="0.017" radius="0.033"/>
      </geometry>
    </collision>
  </link>
  <joint name="left_wheel_joint" type="continuous">
    <origin rpy="0 0 0" xyz="0 0.0485 0"/>
    <parent link="left_motor"/>
    <child link="left_wheel_link"/>
    <axis xyz="0 1 0"/>
  </joint>
  <link name="right_motor">
    <inertial>
      <origin xyz="0.0 0 0"/>
      <mass value="0.1"/>
      <inertia ixx="0.001" ixy="0.0" ixz="0.0" iyy="0.001" iyz="0.0" izz="0.001"/>
    </inertial>
    <visual>
      <origin rpy="1.570795 0 0" xyz="0 0 0"/>
      <geometry>
        <cylinder length="0.08" radius="0.02"/>
      </geometry>
      <material name="gray"/>
    </visual>
    <collision>
      <origin rpy="1.570795 0 0" xyz="0 0 0"/>
      <geometry>
        <cylinder length="0.08" radius="0.02"/>
      </geometry>
    </collision>
  </link>
  <joint name="base_right_motor_joint" type="fixed">
    <origin rpy="0 0 0" xyz="-0.055 -0.075 0"/>
    <parent link="base_link"/>
    <child link="right_motor"/>
  </joint>
  <link name="right_wheel_link">
    <inertial>
      <origin xyz="0 0 0"/>
      <mass value="0.01"/>
      <inertia ixx="0.001" ixy="0.0" ixz="0.0" iyy="0.001" iyz="0.0" izz="0.001"/>
    </inertial>
    <visual>
      <origin rpy="1.570795 0 0" xyz="0 0 0"/>
      <geometry>
        <cylinder length="0.017" radius="0.033"/>
      </geometry>
      <material name="white">
        <color rgba="1 1 1 0.9"/>
      </material>
    </visual>
    <collision>
      <origin rpy="1.570795 0 0" xyz="0 0 0"/>
      <geometry>
        <cylinder length="0.017" radius="0.033"/>
      </geometry>
    </collision>
  </link>
  <joint name="right_wheel_joint" type="continuous">
    <origin rpy="0 0 0" xyz="0 -0.0485 0"/>
    <parent link="right_motor"/>
    <child link="right_wheel_link"/>
    <axis xyz="0 1 0"/>
  </joint>
  <link name="front_caster_link">
    <inertial>
      <origin xyz="0 0 0"/>
      <mass value="0.001"/>
      <inertia ixx="0.0001" ixy="0.0" ixz="0.0" iyy="0.0001" iyz="0.0" izz="0.0001"/>
    </inertial>
    <visual>
      <origin rpy="1.570795 0 0" xyz="0 0 0"/>
      <geometry>
        <sphere radius="0.0165"/>
      </geometry>
      <material name="black"/>
    </visual>
    <collision>
      <origin rpy="1.570795 0 0" xyz="0 0 0.01"/>
      <geometry>
        <sphere radius="0.0165"/>
      </geometry>
    </collision>
  </link>
  <joint name="front_caster_joint" type="fixed">
    <origin rpy="0 0 0" xyz="0.1135 0 -0.0165"/>
    <parent link="base_link"/>
    <child link="front_caster_link"/>
  </joint>
  <joint name="standoff_2in_1_joint" type="fixed">
    <origin rpy="0 0 0" xyz="-0.09 -0.07 0.035"/>
    <parent link="base_link"/>
    <child link="standoff_2in_1_link"/>
  </joint>
  <link name="standoff_2in_1_link">
    <inertial>
      <mass value="0.001"/>
      <origin xyz="0 0 0"/>
      <inertia ixx="0.0001" ixy="0.0" ixz="0.0" iyy="0.0001" iyz="0.0" izz="0.0001"/>
    </inertial>
    <visual>
      <origin rpy="0 0 0" xyz=" 0 0 0 "/>
      <geometry>
        <box size="0.01 0.01 0.07"/>
      </geometry>
      <material name="black">
        <color rgba="0.16 0.17 0.15 0.9"/>
      </material>
    </visual>
    <collision>
      <origin rpy="0 0 0" xyz="0.0 0.0 0.0"/>
      <geometry>
        <box size="0.01 0.01 0.07"/>
      </geometry>
    </collision>
  </link>
  <joint name="standoff_2in_2_joint" type="fixed">
    <origin rpy="0 0 0" xyz="-0.09 0.07 0.035"/>
    <parent link="base_link"/>
    <child link="standoff_2in_2_link"/>
  </joint>
  <link name="standoff_2in_2_link">
    <inertial>
      <mass value="0.001"/>
      <origin xyz="0 0 0"/>
      <inertia ixx="0.0001" ixy="0.0" ixz="0.0" iyy="0.0001" iyz="0.0" izz="0.0001"/>
    </inertial>
    <visual>
      <origin rpy="0 0 0" xyz=" 0 0 0 "/>
      <geometry>
        <box size="0.01 0.01 0.07"/>
      </geometry>
      <material name="black">
        <color rgba="0.16 0.17 0.15 0.9"/>
      </material>
    </visual>
    <collision>
      <origin rpy="0 0 0" xyz="0.0 0.0 0.0"/>
      <geometry>
        <box size="0.01 0.01 0.07"/>
      </geometry>
    </collision>
  </link>
  <joint name="standoff_2in_3_joint" type="fixed">
    <origin rpy="0 0 0" xyz="0.06 -0.1 0.035"/>
    <parent link="base_link"/>
    <child link="standoff_2in_3_link"/>
  </joint>
  <link name="standoff_2in_3_link">
    <inertial>
      <mass value="0.001"/>
      <origin xyz="0 0 0"/>
      <inertia ixx="0.0001" ixy="0.0" ixz="0.0" iyy="0.0001" iyz="0.0" izz="0.0001"/>
    </inertial>
    <visual>
      <origin rpy="0 0 0" xyz=" 0 0 0 "/>
      <geometry>
        <box size="0.01 0.01 0.07"/>
      </geometry>
      <material name="black">
        <color rgba="0.16 0.17 0.15 0.9"/>
      </material>
    </visual>
    <collision>
      <origin rpy="0 0 0" xyz="0.0 0.0 0.0"/>
      <geometry>
        <box size="0.01 0.01 0.07"/>
      </geometry>
    </collision>
  </link>
  <joint name="standoff_2in_4_joint" type="fixed">
    <origin rpy="0 0 0" xyz="0.06 0.1 0.035"/>
    <parent link="base_link"/>
    <child link="standoff_2in_4_link"/>
  </joint>
  <link name="standoff_2in_4_link">
    <inertial>
      <mass value="0.001"/>
      <origin xyz="0 0 0"/>
      <inertia ixx="0.0001" ixy="0.0" ixz="0.0" iyy="0.0001" iyz="0.0" izz="0.0001"/>
    </inertial>
    <visual>
      <origin rpy="0 0 0" xyz=" 0 0 0 "/>
      <geometry>
        <box size="0.01 0.01 0.07"/>
      </geometry>
      <material name="black">
        <color rgba="0.16 0.17 0.15 0.9"/>
      </material>
    </visual>
    <collision>
      <origin rpy="0 0 0" xyz="0.0 0.0 0.0"/>
      <geometry>
        <box size="0.01 0.01 0.07"/>
      </geometry>
    </collision>
  </link>
  <joint name="plate_1_joint" type="fixed">
    <origin rpy="0 0 0" xyz="0 0 0.07"/>
    <parent link="base_link"/>
    <child link="plate_1_link"/>
  </joint>
  <link name="plate_1_link">
    <inertial>
      <mass value="0.1"/>
      <origin xyz="0 0 0"/>
      <inertia ixx="0.01" ixy="0.0" ixz="0.0" iyy="0.01" iyz="0.0" izz="0.01"/>
    </inertial>
    <visual>
      <origin rpy="0 0 0" xyz=" 0 0 0 "/>
      <geometry>
        <cylinder length="0.005" radius="0.13"/>
      </geometry>
      <material name="yellow"/>
    </visual>
    <collision>
      <origin rpy="0 0 0" xyz="0.0 0.0 0.0"/>
      <geometry>
        <cylinder length="0.005" radius="0.13"/>
      </geometry>
    </collision>
  </link>
  <joint name="standoff_2in_5_joint" type="fixed">
    <origin rpy="0 0 0" xyz="0 0 0.07"/>
    <parent link="standoff_2in_1_link"/>
    <child link="standoff_2in_5_link"/>
  </joint>
  <link name="standoff_2in_5_link">
    <inertial>
      <mass value="0.001"/>
      <origin xyz="0 0 0"/>
      <inertia ixx="0.0001" ixy="0.0" ixz="0.0" iyy="0.0001" iyz="0.0" izz="0.0001"/>
    </inertial>
    <visual>
      <origin rpy="0 0 0" xyz=" 0 0 0 "/>
      <geometry>
        <box size="0.01 0.01 0.07"/>
      </geometry>
      <material name="black">
        <color rgba="0.16 0.17 0.15 0.9"/>
      </material>
    </visual>
    <collision>
      <origin rpy="0 0 0" xyz="0.0 0.0 0.0"/>
      <geometry>
        <box size="0.01 0.01 0.07"/>
      </geometry>
    </collision>
  </link>
  <joint name="standoff_2in_6_joint" type="fixed">
    <origin rpy="0 0 0" xyz="0 0 0.07"/>
    <parent link="standoff_2in_2_link"/>
    <child link="standoff_2in_6_link"/>
  </joint>
  <link name="standoff_2in_6_link">
    <inertial>
      <mass value="0.001"/>
      <origin xyz="0 0 0"/>
      <inertia ixx="0.0001" ixy="0.0" ixz="0.0" iyy="0.0001" iyz="0.0" izz="0.0001"/>
    </inertial>
    <visual>
      <origin rpy="0 0 0" xyz=" 0 0 0 "/>
      <geometry>
        <box size="0.01 0.01 0.07"/>
      </geometry>
      <material name="black">
        <color rgba="0.16 0.17 0.15 0.9"/>
      </material>
    </visual>
    <collision>
      <origin rpy="0 0 0" xyz="0.0 0.0 0.0"/>
      <geometry>
        <box size="0.01 0.01 0.07"/>
      </geometry>
    </collision>
  </link>
  <joint name="standoff_2in_7_joint" type="fixed">
    <origin rpy="0 0 0" xyz="0 0 0.07"/>
    <parent link="standoff_2in_3_link"/>
    <child link="standoff_2in_7_link"/>
  </joint>
  <link name="standoff_2in_7_link">
    <inertial>
      <mass value="0.001"/>
      <origin xyz="0 0 0"/>
      <inertia ixx="0.0001" ixy="0.0" ixz="0.0" iyy="0.0001" iyz="0.0" izz="0.0001"/>
    </inertial>
    <visual>
      <origin rpy="0 0 0" xyz=" 0 0 0 "/>
      <geometry>
        <box size="0.01 0.01 0.07"/>
      </geometry>
      <material name="black">
        <color rgba="0.16 0.17 0.15 0.9"/>
      </material>
    </visual>
    <collision>
      <origin rpy="0 0 0" xyz="0.0 0.0 0.0"/>
      <geometry>
        <box size="0.01 0.01 0.07"/>
      </geometry>
    </collision>
  </link>
  <joint name="standoff_2in_8_joint" type="fixed">
    <origin rpy="0 0 0" xyz="0 0 0.07"/>
    <parent link="standoff_2in_4_link"/>
    <child link="standoff_2in_8_link"/>
  </joint>
  <link name="standoff_2in_8_link">
    <inertial>
      <mass value="0.001"/>
      <origin xyz="0 0 0"/>
      <inertia ixx="0.0001" ixy="0.0" ixz="0.0" iyy="0.0001" iyz="0.0" izz="0.0001"/>
    </inertial>
    <visual>
      <origin rpy="0 0 0" xyz=" 0 0 0 "/>
      <geometry>
        <box size="0.01 0.01 0.07"/>
      </geometry>
      <material name="black">
        <color rgba="0.16 0.17 0.15 0.9"/>
      </material>
    </visual>
    <collision>
      <origin rpy="0 0 0" xyz="0.0 0.0 0.0"/>
      <geometry>
        <box size="0.01 0.01 0.07"/>
      </geometry>
    </collision>
  </link>
  <joint name="plate_2_joint" type="fixed">
    <origin rpy="0 0 0" xyz="0 0 0.07"/>
    <parent link="plate_1_link"/>
    <child link="plate_2_link"/>
  </joint>
  <link name="plate_2_link">
    <inertial>
      <mass value="0.01"/>
      <origin xyz="0 0 0"/>
      <inertia ixx="0.001" ixy="0.0" ixz="0.0" iyy="0.001" iyz="0.0" izz="0.001"/>
    </inertial>
    <visual>
      <origin rpy="0 0 0" xyz=" 0 0 0 "/>
      <geometry>
        <cylinder length="0.005" radius="0.13"/>
      </geometry>
      <material name="yellow"/>
    </visual>
    <collision>
      <origin rpy="0 0 0" xyz="0.0 0.0 0.0"/>
      <geometry>
        <cylinder length="0.005" radius="0.13"/>
      </geometry>
    </collision>
  </link>
</robot>

